<?xml version="1.0"?>
<robot xmlns:xacro="http://ros.org/wiki/xacro" name="CPRMover6">

<!-- URDF file for the Commonplace Robotics Mover4 robot arm -->
<!-- Version 1.1 from Oct. 04th, 2016. -->

  <!-- Properties -->
  <xacro:property name="PI" value="3.14159265359"/>
  

  <link name="base_link">
    <visual>
	  <origin rpy="0 0 0" xyz="0 0 0"/>
      <geometry>
          <mesh filename="package://mover6_description/src/description/CPRMover6/Joint0.dae"  scale="0.001 0.001 0.001"/>
        </geometry>
    </visual>
    <collision>
      <origin xyz="0 0 0" rpy="0 0 0" />
      <geometry>
          <mesh filename="package://mover6_description/src/description/CPRMover6/Joint0Coll.dae" scale="0.001 0.001 0.001"/>
        </geometry>
    </collision>
  </link>
  <link name="link1">
    <visual>
	  <origin rpy="0 0 0" xyz="0 0 0"/>
      <geometry>
          <mesh filename="package://mover6_description/src/description/CPRMover6/Joint1.dae"  scale="0.001 0.001 0.001"/>
        </geometry>
    </visual>
    <collision>
      <origin xyz="0 0 0" rpy="0 0 0" />
      <geometry>
          <mesh filename="package://mover6_description/src/description/CPRMover6/Joint1Coll.dae" scale="0.001 0.001 0.001"/>
        </geometry>
    </collision>
  </link>
  <link name="link2">
    <visual>
	  <origin rpy="0 0 0" xyz="0 0 0"/>
      <geometry>
          <mesh filename="package://mover6_description/src/description/CPRMover6/Joint2.dae"  scale="0.001 0.001 0.001"/>
        </geometry>
    </visual>
    <collision>
      <origin xyz="0 0 0" rpy="0 0 0" />
      <geometry>
          <mesh filename="package://mover6_description/src/description/CPRMover6/Joint2Coll.dae" scale="0.001 0.001 0.001"/>
        </geometry>
    </collision>
  </link>
  <link name="link3">
    <visual>
	  <origin rpy="0 0 0" xyz="0 0 0"/>
      <geometry>
          <mesh filename="package://mover6_description/src/description/CPRMover6/Joint3.dae"  scale="0.001 0.001 0.001"/>
        </geometry>
    </visual>
    <collision>
      <origin xyz="0 0 0" rpy="0 0 0" />
      <geometry>
          <mesh filename="package://mover6_description/src/description/CPRMover6/Joint3Coll.dae" scale="0.001 0.001 0.001"/>
        </geometry>
    </collision>
  </link>
  <link name="link4">
    <visual>
	  <origin rpy="0 0 0" xyz="0 0 0"/>
      <geometry>
          <mesh filename="package://mover6_description/src/description/CPRMover6/Joint4.dae"  scale="0.001 0.001 0.001"/>
        </geometry>
    </visual>
    <collision>
      <origin xyz="0 0 0" rpy="0 0 0" />
      <geometry>
          <mesh filename="package://mover6_description/src/description/CPRMover6/Joint4Coll.dae" scale="0.001 0.001 0.001"/>
        </geometry>
    </collision>
  </link>
  <link name="link5">
    <visual>
	  <origin rpy="0 0 0" xyz="0 0 0"/>
      <geometry>
          <mesh filename="package://mover6_description/src/description/CPRMover6/Joint5.dae"  scale="0.001 0.001 0.001"/>
        </geometry>
    </visual>
    <collision>
      <origin xyz="0 0 0" rpy="0 0 0" />
      <geometry>
          <mesh filename="package://mover6_description/src/description/CPRMover6/Joint5Coll.dae" scale="0.001 0.001 0.001"/>
        </geometry>
    </collision>
  </link>
  <link name="link6">
    <visual>
	  <origin rpy="0 0 0" xyz="0 0 0"/>
      <geometry>
          <mesh filename="package://mover6_description/src/description/CPRMover6/Joint6.dae"  scale="0.001 0.001 0.001"/>
        </geometry>
    </visual>
    <collision>
      <origin xyz="0 0 0" rpy="0 0 0" />
      <geometry>
          <mesh filename="package://mover6_description/src/description/CPRMover6/Joint6Coll.dae" scale="0.001 0.001 0.001"/>
        </geometry>
    </collision>
  </link>
  <joint name="joint1" type="continuous">
    <axis xyz="0 0 -1"/>
    <parent link="base_link"/>
    <child link="link1"/>
    <origin rpy="0 0 0" xyz="0 0 0.130"/>
    <limit effort="100" velocity="30"/>
    <joint_properties damping="0.0" friction="0.0"/>
  </joint>
  <joint name="joint2" type="continuous">
    <axis xyz="0 1 0"/>
    <parent link="link1"/>
    <child link="link2"/>
    <origin rpy="0 0 0" xyz="0 0 0.0625"/>
    <limit effort="100" velocity="30"/>
    <joint_properties damping="0.0" friction="0.0"/>
  </joint>
 <joint name="joint3" type="continuous">
    <axis xyz="0 1 0"/>
    <parent link="link2"/>
    <child link="link3"/>
    <origin rpy="0 1.57079632679 0" xyz="0 0 0.190"/>
    <limit effort="100" velocity="30"/>
    <joint_properties damping="0.0" friction="0.0"/>
  </joint>
 <joint name="joint4" type="continuous">
    <axis xyz="0 0 1"/>
    <parent link="link3"/>
    <child link="link4"/>
    <origin rpy="0 0 0" xyz="-0.06 0 0"/>
    <limit effort="100" velocity="30"/>
    <joint_properties damping="0.0" friction="0.0"/>
  </joint>
 <joint name="joint5" type="continuous">
    <axis xyz="0 1 0"/>
    <parent link="link4"/>
    <child link="link5"/>
    <origin rpy="0 0 0" xyz="0 0 0.290"/>
    <limit effort="100" velocity="30"/>
    <joint_properties damping="0.0" friction="0.0"/>
  </joint>
 <joint name="joint6" type="continuous">
    <axis xyz="0 0 1"/>
    <parent link="link5"/>
    <child link="link6"/>
    <origin rpy="0 0 0" xyz="0 0 0.055"/>
    <limit effort="100" velocity="30"/>
    <joint_properties damping="0.0" friction="0.0"/>
  </joint>

  <!-- ROS2_control -->

  <!-- <ros2_control name="${name}" type="system">
      <hardware>
        <plugin>mover6_description/RobotSystem</plugin>
      </hardware>

      <joint name="joint_1">
        <command_interface name="position">
          <param name="min">{-2*pi}</param>
          <param name="max">{2*pi}</param>
        </command_interface>
        <command_interface name="velocity">
          <param name="min">-3.15</param>
          <param name="max">3.15</param>
        </command_interface>
        <state_interface name="position">
          <param name="initial_value">0.0</param>
        </state_interface>
        <state_interface name="velocity"/>
      </joint>

      <joint name="joint_2">
        <command_interface name="position">
          <param name="min">{-2*pi}</param>
          <param name="max">{2*pi}</param>
        </command_interface>
        <command_interface name="velocity">
          <param name="min">-3.15</param>
          <param name="max">3.15</param>
        </command_interface>
        <state_interface name="position">
          <param name="initial_value">0.0</param>
        </state_interface>
        <state_interface name="velocity"/>
      </joint>

      <joint name="joint_3">
        <command_interface name="position">
          <param name="min">{-pi}</param>
          <param name="max">{pi}</param>
        </command_interface>
        <command_interface name="velocity">
          <param name="min">-3.15</param>
          <param name="max">3.15</param>
        </command_interface>
        <state_interface name="position">
          <param name="initial_value">0.0</param>
        </state_interface>
        <state_interface name="velocity"/>
      </joint>

      <joint name="joint_4">
        <command_interface name="position">
          <param name="min">{-2*pi}</param>
          <param name="max">{2*pi}</param>
        </command_interface>
        <command_interface name="velocity">
          <param name="min">-3.2</param>
          <param name="max">3.2</param>
        </command_interface>
        <state_interface name="position">
          <param name="initial_value">0.0</param>
        </state_interface>
        <state_interface name="velocity"/>
      </joint>

      <joint name="joint_5">
        <command_interface name="position">
          <param name="min">{-2*pi}</param>
          <param name="max">{2*pi}</param>
        </command_interface>
        <command_interface name="velocity">
          <param name="min">-3.2</param>
          <param name="max">3.2</param>
        </command_interface>
        <state_interface name="position">
          <param name="initial_value">0.0</param>
        </state_interface>
        <state_interface name="velocity"/>
      </joint>

      <joint name="joint_6">
        <command_interface name="position">
          <param name="min">{-2*pi}</param>
          <param name="max">{2*pi}</param>
        </command_interface>
        <command_interface name="velocity">
          <param name="min">-3.2</param>
          <param name="max">3.2</param>
        </command_interface>
        <state_interface name="position">
          <param name="initial_value">0.0</param>
        </state_interface>
        <state_interface name="velocity"/>
      </joint>

    </ros2_control> -->

</robot>

